Workbook

Sheet Master
A1: ZONE # | B1: ZONE DESCRIPTION
A2: Z501
A3: Z502
A4: Z503
A5: Z504
A6: Z505
A7: Z506
A8: Z507
A9: Z508
A10: Z509
A11: Z510
A12: Z511
A13: Z512
... A15: Z514
A16: Z515 | B16: PS-1: A/C LOSS
A17: Z516 | B17: PS-1: BATT. TRBL
A18: Z517
A19: Z518
A20: Z519
A21: Z520
A22: Z521
A23: Z522
A24: Z523
A25: Z524
A26: Z525
A27: Z526
A28: Z527
A29: Z528
... A31: Z530
A32: Z531 | B32: PS-2: A/C LOSS
A33: Z532 | B33: PS-2: BATT. TRBL
A34: Z533
A35: Z534
A36: Z535
A37: Z536
A38: Z537
A39: Z538
A40: Z539
A41: Z540
A42: Z541
...

Sheet SITE INFO
A6: DMP INSTALLATION WORKSHEET
A10: School Name:
A12: School Code:
A14: School Main Phone:
A16: DMP 2 Back-Up Phone:
A18: Install Tech: | B18: ConvergeOne Inc.
A20: Install Date:
A22: Panel Type (Include Version) | B22: DMP XR550
A24: IP Address:
A25: SUBNET MASK | B25: 255.255.255.0
A26: DEFAULT GATEWAY
A27: DNS Server | B27: 10.10.1.34

Sheet DMP XR550
A1: DMP XR550 DNL-G Control Main Panel
A3: BOARD TYPE / NUMBER | B3: POINTS | D3: LOCATION OF BOARD
A4: DMP XR550 # | B4: N/A
A12: Bus NUMBER | B12: POINTS | D12: Name of Buildings
A13: LX Bus 500 | B13: LX714-1 | C13: 501-516
B14: LX714-2 | C14: 517-532
B15: LX714-3 | C15: 533-548
B16: LX714-4 | C16: 549-564
B17: LX714-5 | C17: 565-580
B18: LX714-6 | C18: 581-596
A19: LX Bus 600 | B19: LX714-7 | C19: 601-616
B20: LX714-8 | C20: 617-632
B21: LX714-9 | C21: 633-648
B22: LX714-10 | C22: 649-664
B23: LX714-11 | C23: 665-680
B24: LX714-12 | C24: 681-696
A25: LX Bus 700 | B25: LX714-13 | C25: 701-716
B26: LX714-14 | C26: 717-732
B27: LX714-15 | C27: 733-748
B28: LX714-16 | C28: 749-764
B29: LX714-17 | C29: 765-780
B30: LX714-18 | C30: 781-796
A31: LX Bus 800 | B31: LX714-19 | C31: 801-816
B32: LX714-20 | C32: 817-832
B33: LX714-21 | C33: 833-848
B34: LX714-22 | C34: 849-864
B35: LX714-23 | C35: 865-880
B36: LX714-24 | C36: 881-896
A37: LX Bus 900 | B37: LX714-25 | C37: 901-916
B38: LX714-26 | C38: 917-932
B39: LX714-27 | C39: 933-948
B40: LX714-28 | C40: 949-964
B41: LX714-29 | C41: 965-980
B42: LX714-30 | C42: 981-996

Sheet Keypad
A1: DMP 7060-W Keypad Information
A2: KEYPAD MODULE # | B2: Source | C2: GLOBAL Y / N | D2: LOCATION OF KEYPAD
A3: 1 | B3: KP-710-N | C3: Y
A4: 2 | B4: KP-710-N | C4: Y
A5: 3 | B5: KP-710-N | C5: Y
A6: 4 | B6: KP-710-N | C6: Y
A7: 5 | B7: KP-710-N | C7: Y
A8: 6 | B8: KP-710-N | C8: Y

Sheet 710 Splitter-Repeater(KP-Bus) 
A1: 710 Bus Splitter/Repeater Modules | B1: FUNCTION / PURPOSE | D1: LOCATION OF BOARD
A2: KP-710-N | B2: KP-Bus In
B3: KP-Bus 1
B4: KP-Bus 2
B5: KP-Bus 3
A6: KP-710-N | B6: KP-Bus In
B7: KP-Bus 1
B8: KP-Bus 2
B9: KP-Bus 3
A10: KP-710-N | B10: KP-Bus In
B11: KP-Bus 1
B12: KP-Bus 2
B13: KP-Bus 3
A14: KP-710-N | B14: KP-Bus In
B15: KP-Bus 1
B16: KP-Bus 2
B17: KP-Bus 3
A18: KP-710-N | B18: KP-Bus In
B19: KP-Bus 1
B20: KP-Bus 2
B21: KP-Bus 3
A22: KP-710-N | B22: KP-Bus In
B23: KP-Bus 1
B24: KP-Bus 2
B25: KP-Bus 3
A26: KP-710-N | B26: KP-Bus In
B27: KP-Bus 1
B28: KP-Bus 2
B29: KP-Bus 3
A30: KP-710-N | B30: KP-Bus In
B31: KP-Bus 1
B32: KP-Bus 2
B33: KP-Bus 3

Sheet 710 Splitter-Repeater LXBus
A1: 710 Bus Splitter/Repeater Modules | B1: FUNCTION / PURPOSE | D1: LOCATION OF BOARD
A2: 710-LX500-1 | B2: LX-Bus In
B3: LX-Bus 1
B4: LX-Bus 2
B5: LX-Bus 3
A6: 710-LX500-2 | B6: LX-Bus In
B7: LX-Bus 1
B8: LX-Bus 2
B9: LX-Bus 3
A10: 710-LX500-3 | B10: LX-Bus In
B11: LX-Bus 1
B12: LX-Bus 2
B13: LX-Bus 3
A14: 710-LX500-4 | B14: LX-Bus In
B15: LX-Bus 1
B16: LX-Bus 2
B17: LX-Bus 3
A18: 710-LX600-1 | B18: LX-Bus In
B19: LX-Bus 1
B20: LX-Bus 2
B21: LX-Bus 3
A22: 710-LX600-2 | B22: LX-Bus In
B23: LX-Bus 1
B24: LX-Bus 2
B25: LX-Bus 3
A26: 710-LX600-3 | B26: LX-Bus In
B27: LX-Bus 1
B28: LX-Bus 2
B29: LX-Bus 3
A30: 710-LX600-4 | B30: LX-Bus In
B31: LX-Bus 1
B32: LX-Bus 2
B33: LX-Bus 3
A34: 710-LX700-1 | B34: LX-Bus In
B35: LX-Bus 1
B36: LX-Bus 2
B37: LX-Bus 3
A38: 710-LX700-2 | B38: LX-Bus In
B39: LX-Bus 1
B40: LX-Bus 2
...

Sheet DMP 505-12_G Power Supply 1-10
A1: DMP505-12G NUMBER | B1: FUNCTION / PURPOSE | D1: LOCATION OF BOARD
A2: 1 | B2: RELAY 1 | C2: Auxiliary Power
B3: RELAY 2 | C3: AC trouble zone 515 ( 714-16 expander #1)
B4: RELAY 3 | C4: Battery trouble zone 516 ( 714-16 expander #1)
B5: RELAY 4
A6: 2 | B6: RELAY 1 | C6: Auxiliary Power
B7: RELAY 2 | C7: AC trouble zone 531 ( 714-16 expander #2)
B8: RELAY 3 | C8: Battery trouble zone 532 ( 714-16 expander #2)
B9: RELAY 4
A10: 3 | B10: RELAY 1 | C10: Auxiliary Power
B11: RELAY 2 | C11: AC trouble zone 547 ( 714-16 expander #3)
B12: RELAY 3 | C12: Battery trouble zone 548 ( 714-16 expander #3)
B13: RELAY 4
A14: 4 | B14: RELAY 1 | C14: Auxiliary Power
B15: RELAY 2 | C15: AC trouble zone 563 ( 714-16 expander #4)
B16: RELAY 3 | C16: Battery trouble zone 564 ( 714-16 expander #4)
B17: RELAY 4
A18: 5 | B18: RELAY 1 | C18: Auxiliary Power
B19: RELAY 2 | C19: AC trouble zone 579 ( 714-16 expander #5)
B20: RELAY 3 | C20: Battery trouble zone 580 ( 714-16 expander #5)
B21: RELAY 4
A22: 6 | B22: RELAY 1 | C22: Auxiliary Power
B23: RELAY 2 | C23: AC trouble zone 595 ( 714-16 expander #6)
B24: RELAY 3 | C24: Battery trouble zone 596 ( 714-16 expander #6)
B25: RELAY 4
A26: 7 | B26: RELAY 1 | C26: Auxiliary Power
B27: RELAY 2 | C27: AC trouble zone 615 ( 714-16 expander #7)
B28: RELAY 3 | C28: Battery trouble zone 616 ( 714-16 expander #7)
B29: RELAY 4
A30: 8 | B30: RELAY 1 | C30: Auxiliary Power
B31: RELAY 2 | C31: AC trouble zone 631 ( 714-16 expander #8)
B32: RELAY 3 | C32: Battery trouble zone 632 ( 714-16 expander #8)
B33: RELAY 4
A34: 9 | B34: RELAY 1 | C34: Auxiliary Power
B35: RELAY 2 | C35: AC trouble zone 647 ( 714-16 expander #9)
B36: RELAY 3 | C36: Battery trouble zone 648 ( 714-16 expander #9)
B37: RELAY 4
A38: 10 | B38: RELAY 1 | C38: Auxiliary Power
B39: RELAY 2 | C39: AC trouble zone 663 ( 714-16 expander #10)
B40: RELAY 3 | C40: Battery trouble zone 664 ( 714-16 expander #10)
...

Sheet DMP 714 Exp Mod
A1: DMP 714-16 or 714-08 EXPANSION MODULES
A3: DMP 714- * NUMBER | C3: POINTS | D3: LOCATION OF BOARD
A4: DMP 714-16 # | B4: 1 | C4: 501 - 516
A5: DMP 714-16 # | B5: 2 | C5: 517 - 532
A6: DMP 714-16 # | B6: 3 | C6: 533 - 548
A7: DMP 714-16 # | B7: 4 | C7: 601 - 616
A8: DMP 714-16 # | B8: 5 | C8: 617 - 632
A9: DMP 714-16 # | B9: 6 | C9: 633 - 648
A10: DMP 714-16 # | B10: 7 | C10: 649 - 664
A11: DMP 714-16 # | B11: 8 | C11: 701 - 716
A12: DMP 714-16 # | B12: 9 | C12: 717 - 732
A13: DMP 714-16 # | B13: 10 | C13: 733 - 748
A14: DMP 714-16 # | B14: 11 | C14: 801-816
A15: DMP 714-16 # | B15: 12 | C15: 817-832
... A18: DMP 714-16 # | B18: 15 | C18: 865-880

Sheet DMP 714 Point Info 1
A1: POINT INFORMATION
A3: DMP POINTS | B3: LOCATION OF DEVICES | D3: PARTITION # | E3: REPORT # | F3: DEVICE TYPE
A4: =Master!A2 -> Z501 | B4: =Master!B2 -> 0 | D4: 1 | F4: Motion
A5: =Master!A3 -> Z502 | B5: =Master!B3 -> 0 | D5: 1 | F5: Motion
A6: =Master!A4 -> Z503 | B6: =Master!B4 -> 0 | D6: 1 | F6: Motion
A7: =Master!A5 -> Z504 | B7: =Master!B5 -> 0 | D7: 1 | F7: Motion
A8: =Master!A6 -> Z505 | B8: =Master!B6 -> 0 | D8: 1 | F8: Motion
A9: =Master!A7 -> Z506 | B9: =Master!B7 -> 0 | D9: 1 | F9: Motion
A10: =Master!A8 -> Z507 | B10: =Master!B8 -> 0 | D10: 1 | F10: Motion
A11: =Master!A9 -> Z508 | B11: =Master!B9 -> 0 | D11: 1 | F11: Motion
A12: =Master!A10 -> Z509 | B12: =Master!B10 -> 0 | D12: 1 | F12: Motion
A13: =Master!A11 -> Z510 | B13: =Master!B11 -> 0 | D13: 1 | F13: Motion
A14: =Master!A12 -> Z511 | B14: =Master!B12 -> 0 | D14: 1 | F14: Motion
A15: =Master!A13 -> Z512 | B15: =Master!B13 -> 0 | D15: 1 | F15: Motion
... A19: =Master!A17 -> Z516 | B19: =Master!B17 -> PS-1: BATT. TRBL | D19: 1 | F19: Supervisory
A20: Source: DMP 714-16 Expander #1

Sheet DMP 714 Point Info 2
A1: POINT INFORMATION
A3: DMP POINTS | B3: LOCATION OF DEVICES | D3: PARTITION # | E3: REPORT # | F3: DEVICE TYPE
A4: =Master!A18 -> Z517 | B4: =Master!B18 -> 0 | D4: 1 | F4: Motion
A5: =Master!A19 -> Z518 | B5: =Master!B19 -> 0 | D5: 1 | F5: Motion
A6: =Master!A20 -> Z519 | B6: =Master!B20 -> 0 | D6: 1 | F6: Motion
A7: =Master!A21 -> Z520 | B7: =Master!B21 -> 0 | D7: 1 | F7: Motion
A8: =Master!A22 -> Z521 | B8: =Master!B22 -> 0 | D8: 1 | F8: Motion
A9: =Master!A23 -> Z522 | B9: =Master!B23 -> 0 | D9: 1 | F9: Motion
A10: =Master!A24 -> Z523 | B10: =Master!B24 -> 0 | D10: 1 | F10: Motion
A11: =Master!A25 -> Z524 | B11: =Master!B25 -> 0 | D11: 1 | F11: Motion
A12: =Master!A26 -> Z525 | B12: =Master!B26 -> 0 | D12: 1 | F12: Motion
A13: =Master!A27 -> Z526 | B13: =Master!B27 -> 0 | D13: 1 | F13: Motion
A14: =Master!A28 -> Z527 | B14: =Master!B28 -> 0 | D14: 1 | F14: Motion
A15: =Master!A29 -> Z528 | B15: =Master!B29 -> 0 | D15: 1 | F15: Motion
... A19: =Master!A33 -> Z532 | B19: =Master!B33 -> PS-2: BATT. TRBL | D19: 1 | F19: Supervisory
A20: Source: DMP 714-16 Expander #2

Sheet DMP 714 Point Info 3
A1: POINT INFORMATION
A3: DMP POINTS | B3: LOCATION OF DEVICES | D3: PARTITION # | E3: REPORT # | F3: DEVICE TYPE
A4: =Master!A34 -> Z533 | B4: =Master!B34 -> 0 | D4: 1 | F4: Motion
A5: =Master!A35 -> Z534 | B5: =Master!B35 -> 0 | D5: 1 | F5: Motion
A6: =Master!A36 -> Z535 | B6: =Master!B36 -> 0 | D6: 1 | F6: Motion
A7: =Master!A37 -> Z536 | B7: =Master!B37 -> 0 | D7: 1 | F7: Motion
A8: =Master!A38 -> Z537 | B8: =Master!B38 -> 0 | D8: 1 | F8: Motion
A9: =Master!A39 -> Z538 | B9: =Master!B39 -> 0 | D9: 1 | F9: Motion
A10: =Master!A40 -> Z539 | B10: =Master!B40 -> 0 | D10: 1 | F10: Motion
A11: =Master!A41 -> Z540 | B11: =Master!B41 -> 0 | D11: 1 | F11: Motion
A12: =Master!A42 -> Z541 | B12: =Master!B42 -> 0 | D12: 1 | F12: Motion
A13: =Master!A43 -> Z542 | B13: =Master!B43 -> 0 | D13: 1 | F13: Motion
A14: =Master!A44 -> Z543 | B14: =Master!B44 -> 0 | D14: 1 | F14: Motion
A15: =Master!A45 -> Z544 | B15: =Master!B45 -> 0 | D15: 1 | F15: Motion
... A19: =Master!A49 -> Z548 | B19: =Master!B49 -> PS-3: BATT. TRBL | D19: 1 | F19: Supervisory
A20: Source: DMP 714-16 Expander #3

Sheet DMP 714 Point Info 4
A1: POINT INFORMATION
A3: DMP POINTS | B3: LOCATION OF DEVICES | D3: PARTITION # | E3: REPORT # | F3: DEVICE TYPE
A4: =Master!A50 -> Z549 | B4: =Master!B50 -> 0 | D4: 1 | F4: Motion
A5: =Master!A51 -> Z550 | B5: =Master!B51 -> 0 | D5: 1 | F5: Motion
A6: =Master!A52 -> Z551 | B6: =Master!B52 -> 0 | D6: 1 | F6: Motion
A7: =Master!A53 -> Z552 | B7: =Master!B53 -> 0 | D7: 1 | F7: Motion
A8: =Master!A54 -> Z553 | B8: =Master!B54 -> 0 | D8: 1 | F8: Motion
A9: =Master!A55 -> Z554 | B9: =Master!B55 -> 0 | D9: 1 | F9: Motion
A10: =Master!A56 -> Z555 | B10: =Master!B56 -> 0 | D10: 1 | F10: Motion
A11: =Master!A57 -> Z556 | B11: =Master!B57 -> 0 | D11: 1 | F11: Motion
A12: =Master!A58 -> Z557 | B12: =Master!B58 -> 0 | D12: 1 | F12: Motion
A13: =Master!A59 -> Z558 | B13: =Master!B59 -> 0 | D13: 1 | F13: Motion
A14: =Master!A60 -> Z559 | B14: =Master!B60 -> 0 | D14: 1 | F14: Motion
A15: =Master!A61 -> Z560 | B15: =Master!B61 -> 0 | D15: 1 | F15: Motion
... A19: =Master!A65 -> Z564 | B19: =Master!B65 -> PS-4: BATT. TRBL. | D19: 1 | F19: Supervisory
A20: Source: DMP 714-16 Expander #4

Sheet DMP 714 Point Info 5
A1: POINT INFORMATION
A3: DMP POINTS | B3: LOCATION OF DEVICES | D3: PARTITION # | E3: REPORT # | F3: DEVICE TYPE
A4: =Master!A66 -> Z565 | B4: =Master!B66 -> 0 | D4: 1 | F4: Motion
A5: =Master!A67 -> Z566 | B5: =Master!B67 -> 0 | D5: 1 | F5: Motion
A6: =Master!A68 -> Z567 | B6: =Master!B68 -> 0 | D6: 1 | F6: Motion
A7: =Master!A69 -> Z568 | B7: =Master!B69 -> 0 | D7: 1 | F7: Motion
A8: =Master!A70 -> Z569 | B8: =Master!B70 -> 0 | D8: 1 | F8: Motion
A9: =Master!A71 -> Z570 | B9: =Master!B71 -> 0 | D9: 1 | F9: Motion
A10: =Master!A72 -> Z571 | B10: =Master!B72 -> 0 | D10: 1 | F10: Motion
A11: =Master!A73 -> Z572 | B11: =Master!B73 -> 0 | D11: 1 | F11: Motion
A12: =Master!A74 -> Z573 | B12: =Master!B74 -> 0 | D12: 1 | F12: Motion
A13: =Master!A75 -> Z574 | B13: =Master!B75 -> 0 | D13: 1 | F13: Door Contact
A14: =Master!A76 -> Z575 | B14: =Master!B76 -> 0 | D14: 1 | F14: Door Contact
A15: =Master!A77 -> Z576 | B15: =Master!B77 -> 0 | D15: 1 | F15: Door Contact
... A19: =Master!A81 -> Z580 | B19: =Master!B81 -> PS-5: BATT. TRBL. | D19: 1 | F19: Supervisory
A20: Source: DMP 714-16 Expander #5

Sheet DMP 714 Point Info 6
A1: POINT INFORMATION
A3: DMP POINTS | B3: LOCATION OF DEVICES | D3: PARTITION # | E3: REPORT # | F3: DEVICE TYPE
A4: =Master!A82 -> Z581 | B4: =Master!B82 -> 0 | D4: 1 | F4: Motion
A5: =Master!A83 -> Z582 | B5: =Master!B83 -> 0 | D5: 1 | F5: Motion
A6: =Master!A84 -> Z583 | B6: =Master!B84 -> 0 | D6: 1 | F6: Motion
A7: =Master!A85 -> Z584 | B7: =Master!B85 -> 0 | D7: 1 | F7: Motion
A8: =Master!A86 -> Z585 | B8: =Master!B86 -> 0 | D8: 1 | F8: Motion
A9: =Master!A87 -> Z586 | B9: =Master!B87 -> 0 | D9: 1 | F9: Motion
A10: =Master!A88 -> Z587 | B10: =Master!B88 -> 0 | D10: 1 | F10: Motion
A11: =Master!A89 -> Z588 | B11: =Master!B89 -> 0 | D11: 1 | F11: Motion
A12: =Master!A90 -> Z589 | B12: =Master!B90 -> 0 | D12: 1 | F12: Motion
A13: =Master!A91 -> Z590 | B13: =Master!B91 -> 0 | D13: 1 | F13: Motion
A14: =Master!A92 -> Z591 | B14: =Master!B92 -> 0 | D14: 1 | F14: Motion
A15: =Master!A93 -> Z592 | B15: =Master!B93 -> 0 | D15: 1 | F15: Motion
... A19: =Master!A97 -> Z596 | B19: =Master!B97 -> PS-6: BATT. TRBL. | D19: 1 | F19: Supervisory
A20: Source: DMP 714-16 Expander #6

Sheet DMP 714 Point Info 7
A1: POINT INFORMATION
A3: DMP POINTS | B3: LOCATION OF DEVICES | D3: PARTITION # | E3: REPORT # | F3: DEVICE TYPE
A4: =Master!A98 -> Z601 | B4: =Master!B98 -> 0 | D4: 1 | F4: Motion
A5: =Master!A99 -> Z602 | B5: =Master!B99 -> 0 | D5: 1 | F5: Motion
A6: =Master!A100 -> Z603 | B6: =Master!B100 -> 0 | D6: 1 | F6: Motion
A7: =Master!A101 -> Z604 | B7: =Master!B101 -> 0 | D7: 1 | F7: Motion
A8: =Master!A102 -> Z605 | B8: =Master!B102 -> 0 | D8: 1 | F8: Motion
A9: =Master!A103 -> Z606 | B9: =Master!B103 -> 0 | D9: 1 | F9: Motion
A10: =Master!A104 -> Z607 | B10: =Master!B104 -> 0 | D10: 1 | F10: Motion
A11: =Master!A105 -> Z608 | B11: =Master!B105 -> 0 | D11: 1 | F11: Motion
A12: =Master!A106 -> Z609 | B12: =Master!B106 -> 0 | D12: 1 | F12: Motion
A13: =Master!A107 -> Z610 | B13: =Master!B107 -> 0 | D13: 1 | F13: Motion
A14: =Master!A108 -> Z611 | B14: =Master!B108 -> 0 | D14: 1 | F14: Motion
A15: =Master!A109 -> Z612 | B15: =Master!B109 -> 0 | D15: 1 | F15: Motion
... A19: =Master!A113 -> Z616 | B19: =Master!B113 -> PS-7: BATT. TRBL. | D19: 1 | F19: Supervisory
A20: Source: DMP 714-16 Expander #7

Sheet DMP 714 Point Info 8
A1: POINT INFORMATION
A3: DMP POINTS | B3: LOCATION OF DEVICES | D3: PARTITION # | E3: REPORT # | F3: DEVICE TYPE
A4: =Master!A114 -> Z617 | B4: =Master!B114 -> 0 | D4: 1 | F4: Motion
A5: =Master!A115 -> Z618 | B5: =Master!B115 -> 0 | D5: 1 | F5: Motion
A6: =Master!A116 -> Z619 | B6: =Master!B116 -> 0 | D6: 1 | F6: Motion
A7: =Master!A117 -> Z620 | B7: =Master!B117 -> 0 | D7: 1 | F7: Motion
A8: =Master!A118 -> Z621 | B8: =Master!B118 -> 0 | D8: 1 | F8: Motion
A9: =Master!A119 -> Z622 | B9: =Master!B119 -> 0 | D9: 1 | F9: Motion
A10: =Master!A120 -> Z623 | B10: =Master!B120 -> 0 | D10: 1 | F10: Motion
A11: =Master!A121 -> Z624 | B11: =Master!B121 -> 0 | D11: 1 | F11: Motion
A12: =Master!A122 -> Z625 | B12: =Master!B122 -> 0 | D12: 1 | F12: Motion
A13: =Master!A123 -> Z626 | B13: =Master!B123 -> 0 | D13: 1 | F13: Motion
A14: =Master!A124 -> Z627 | B14: =Master!B124 -> 0 | D14: 1 | F14: Motion
A15: =Master!A125 -> Z628 | B15: =Master!B125 -> 0 | D15: 1 | F15: Motion
... A19: =Master!A129 -> Z632 | B19: =Master!B129 -> PS-8: BATT. TRBL. | D19: 1 | F19: Supervisory
A20: Source: DMP 714-16 Expander #8

Sheet DMP 714 Point Info 9
A1: POINT INFORMATION
A3: DMP POINTS | B3: LOCATION OF DEVICES | D3: PARTITION # | E3: REPORT # | F3: DEVICE TYPE
A4: =Master!A130 -> Z633 | B4: =Master!B130 -> 0 | D4: 1 | F4: Motion
A5: =Master!A131 -> Z634 | B5: =Master!B131 -> 0 | D5: 1 | F5: Motion
A6: =Master!A132 -> Z635 | B6: =Master!B132 -> 0 | D6: 1 | F6: Motion
A7: =Master!A133 -> Z636 | B7: =Master!B133 -> 0 | D7: 1 | F7: Motion
A8: =Master!A134 -> Z637 | B8: =Master!B134 -> 0 | D8: 1 | F8: Motion
A9: =Master!A135 -> Z638 | B9: =Master!B135 -> 0 | D9: 1 | F9: Motion
A10: =Master!A136 -> Z639 | B10: =Master!B136 -> 0 | D10: 1 | F10: Motion
A11: =Master!A137 -> Z640 | B11: =Master!B137 -> 0 | D11: 1 | F11: Motion
A12: =Master!A138 -> Z641 | B12: =Master!B138 -> 0 | D12: 1 | F12: Motion
A13: =Master!A139 -> Z642 | B13: =Master!B139 -> 0 | D13: 1 | F13: Motion
A14: =Master!A140 -> Z643 | B14: =Master!B140 -> 0 | D14: 1 | F14: Motion
A15: =Master!A141 -> Z644 | B15: =Master!B141 -> 0 | D15: 1 | F15: Motion
... A19: =Master!A145 -> Z648 | B19: =Master!B145 -> PS-9: BATT. TRBL. | D19: 1 | F19: Supervisory
A20: Source: DMP 714-16 Expander #9

Sheet DMP 714 Point Info 10
A1: POINT INFORMATION
A3: DMP POINTS | B3: LOCATION OF DEVICES | D3: PARTITION # | E3: REPORT # | F3: DEVICE TYPE
A4: =Master!A146 -> Z649 | B4: =Master!B146 -> 0 | D4: 1 | F4: Motion
A5: =Master!A147 -> Z650 | B5: =Master!B147 -> 0 | D5: 1 | F5: Motion
A6: =Master!A148 -> Z651 | B6: =Master!B148 -> 0 | D6: 1 | F6: Motion
A7: =Master!A149 -> Z652 | B7: =Master!B149 -> 0 | D7: 1 | F7: Motion
A8: =Master!A150 -> Z653 | B8: =Master!B150 -> 0 | D8: 1 | F8: Motion
A9: =Master!A151 -> Z654 | B9: =Master!B151 -> 0 | D9: 1 | F9: Motion
A10: =Master!A152 -> Z655 | B10: =Master!B152 -> 0 | D10: 1 | F10: Motion
A11: =Master!A153 -> Z656 | B11: =Master!B153 -> 0 | D11: 1 | F11: Motion
A12: =Master!A154 -> Z657 | B12: =Master!B154 -> 0 | D12: 1 | F12: Motion
A13: =Master!A155 -> Z658 | B13: =Master!B155 -> 0 | D13: 1 | F13: Motion
A14: =Master!A156 -> Z659 | B14: =Master!B156 -> 0 | D14: 1 | F14: Motion
A15: =Master!A157 -> Z660 | B15: =Master!B157 -> 0 | D15: 1 | F15: Motion
... A19: =Master!A161 -> Z664 | B19: =Master!B161 -> PS-10: BATT. TRBL. | D19: 1 | F19: Supervisory
A20: Source: DMP 714-16 Expander #10

Sheet DMP 714 Point Info 11
A1: POINT INFORMATION
A3: DMP POINTS | B3: LOCATION OF DEVICES | D3: PARTITION # | E3: REPORT # | F3: DEVICE TYPE
A4: =Master!A162 -> Z665 | B4: =Master!B162 -> 0 | D4: 1 | F4: Motion
A5: =Master!A163 -> Z666 | B5: =Master!B163 -> 0 | D5: 1 | F5: Motion
A6: =Master!A164 -> Z667 | B6: =Master!B164 -> 0 | D6: 1 | F6: Motion
A7: =Master!A165 -> Z668 | B7: =Master!B165 -> 0 | D7: 1 | F7: Motion
A8: =Master!A166 -> Z669 | B8: =Master!B166 -> 0 | D8: 1 | F8: Motion
A9: =Master!A167 -> Z670 | B9: =Master!B167 -> 0 | D9: 1 | F9: Motion
A10: =Master!A168 -> Z671 | B10: =Master!B168 -> 0 | D10: 1 | F10: Motion
A11: =Master!A169 -> Z672 | B11: =Master!B169 -> 0 | D11: 1 | F11: Motion
A12: =Master!A170 -> Z673 | B12: =Master!B170 -> 0 | D12: 1 | F12: Motion
A13: =Master!A171 -> Z674 | B13: =Master!B171 -> 0 | D13: 1 | F13: Motion
A14: =Master!A172 -> Z675 | B14: =Master!B172 -> 0 | D14: 1 | F14: Motion
A15: =Master!A173 -> Z676 | B15: =Master!B173 -> 0 | D15: 1 | F15: Motion
... A19: =Master!A177 -> Z680 | B19: =Master!B177 -> PS-11: BATT. TRBL. | D19: 1 | F19: Supervisory
A20: Source: DMP 714-16 Expander #11

Sheet DMP 714 Point Info 12
A1: POINT INFORMATION
A3: DMP POINTS | B3: LOCATION OF DEVICES | D3: PARTITION # | E3: REPORT # | F3: DEVICE TYPE
A4: =Master!A178 -> Z681 | B4: =Master!B178 -> 0 | D4: 1 | F4: Motion
A5: =Master!A179 -> Z682 | B5: =Master!B179 -> 0 | D5: 1 | F5: Motion
A6: =Master!A180 -> Z683 | B6: =Master!B180 -> 0 | D6: 1 | F6: Motion
A7: =Master!A181 -> Z684 | B7: =Master!B181 -> 0 | D7: 1 | F7: Motion
A8: =Master!A182 -> Z685 | B8: =Master!B182 -> 0 | D8: 1 | F8: Motion
A9: =Master!A183 -> Z686 | B9: =Master!B183 -> 0 | D9: 1 | F9: Motion
A10: =Master!A184 -> Z687 | B10: =Master!B184 -> 0 | D10: 1 | F10: Motion
A11: =Master!A185 -> Z688 | B11: =Master!B185 -> 0 | D11: 1 | F11: Motion
A12: =Master!A186 -> Z689 | B12: =Master!B186 -> 0 | D12: 1 | F12: Motion
A13: =Master!A187 -> Z690 | B13: =Master!B187 -> 0 | D13: 1 | F13: Motion
A14: =Master!A188 -> Z691 | B14: =Master!B188 -> 0 | D14: 1 | F14: Motion
A15: =Master!A189 -> Z692 | B15: =Master!B189 -> 0 | D15: 1 | F15: Motion
... A19: =Master!A193 -> Z696 | B19: =Master!B193 -> PS-12: BATT. TRBL. | D19: 1 | F19: Supervisory
A20: Source: DMP 714-16 Expander #12

Sheet DMP 714 Point Info 13
A1: POINT INFORMATION
A3: DMP POINTS | B3: LOCATION OF DEVICES | D3: PARTITION # | E3: REPORT # | F3: DEVICE TYPE
A4: =Master!A194 -> Z701 | B4: =Master!B194 -> 0 | D4: 1 | F4: Motion
A5: =Master!A195 -> Z702 | B5: =Master!B195 -> 0 | D5: 1 | F5: Motion
A6: =Master!A196 -> Z703 | B6: =Master!B196 -> 0 | D6: 1 | F6: Motion
A7: =Master!A197 -> Z704 | B7: =Master!B197 -> 0 | D7: 1 | F7: Motion
A8: =Master!A198 -> Z705 | B8: =Master!B198 -> 0 | D8: 1 | F8: Motion
A9: =Master!A199 -> Z706 | B9: =Master!B199 -> 0 | D9: 1 | F9: Motion
A10: =Master!A200 -> Z707 | B10: =Master!B200 -> 0 | D10: 1 | F10: Motion
A11: =Master!A201 -> Z708 | B11: =Master!B201 -> 0 | D11: 1 | F11: Motion
A12: =Master!A202 -> Z709 | B12: =Master!B202 -> 0 | D12: 1 | F12: Motion
A13: =Master!A203 -> Z710 | B13: =Master!B203 -> 0 | D13: 1 | F13: Motion
A14: =Master!A204 -> Z711 | B14: =Master!B204 -> 0 | D14: 1 | F14: Motion
A15: =Master!A205 -> Z712 | B15: =Master!B205 -> 0 | D15: 1 | F15: Motion
... A19: =Master!A209 -> Z716 | B19: =Master!B209 -> PS-13: BATT. TRBL. | D19: 1 | F19: Supervisory
A20: Source: DMP 714-16 Expander #13

Sheet DMP 714 Point Info 14
A1: POINT INFORMATION
A3: DMP POINTS | B3: LOCATION OF DEVICES | D3: PARTITION # | E3: REPORT # | F3: DEVICE TYPE
A4: =Master!A210 -> Z717 | B4: =Master!B210 -> 0 | D4: 1 | F4: Motion
A5: =Master!A211 -> Z718 | B5: =Master!B211 -> 0 | D5: 1 | F5: Motion
A6: =Master!A212 -> Z719 | B6: =Master!B212 -> 0 | D6: 1 | F6: Motion
A7: =Master!A213 -> Z720 | B7: =Master!B213 -> 0 | D7: 1 | F7: Motion
A8: =Master!A214 -> Z721 | B8: =Master!B214 -> 0 | D8: 1 | F8: Motion
A9: =Master!A215 -> Z722 | B9: =Master!B215 -> 0 | D9: 1 | F9: Motion
A10: =Master!A216 -> Z723 | B10: =Master!B216 -> 0 | D10: 1 | F10: Motion
A11: =Master!A217 -> Z724 | B11: =Master!B217 -> 0 | D11: 1 | F11: Motion
A12: =Master!A218 -> Z725 | B12: =Master!B218 -> 0 | D12: 1 | F12: Motion
A13: =Master!A219 -> Z726 | B13: =Master!B219 -> 0 | D13: 1 | F13: Motion
A14: =Master!A220 -> Z727 | B14: =Master!B220 -> 0 | D14: 1 | F14: Door Contact
A15: =Master!A221 -> Z728 | B15: =Master!B221 -> 0 | D15: 1 | F15: Door Contact
... A19: =Master!A225 -> Z732 | B19: =Master!B225 -> PS-14: BATT. TRBL. | D19: 1 | F19: Supervisory
A20: Source: DMP 714-16 Expander #14

Sheet DMP 714 Point Info 15
A1: POINT INFORMATION
A3: DMP POINTS | B3: LOCATION OF DEVICES | D3: PARTITION # | E3: REPORT # | F3: DEVICE TYPE
A4: =Master!A226 -> Z733 | B4: =Master!B226 -> 0 | D4: 1 | F4: Door Contact
A5: =Master!A227 -> Z734 | B5: =Master!B227 -> 0 | D5: 1 | F5: Door Contact
A6: =Master!A228 -> Z735 | B6: =Master!B228 -> 0 | D6: 1 | F6: Door Contact
A7: =Master!A229 -> Z736 | B7: =Master!B229 -> 0 | D7: 1 | F7: Door Contact
A8: =Master!A230 -> Z737 | B8: =Master!B230 -> 0 | D8: 1 | F8: Door Contact
A9: =Master!A231 -> Z738 | B9: =Master!B231 -> 0 | D9: 1 | F9: Door Contact
A10: =Master!A232 -> Z739 | B10: =Master!B232 -> 0 | D10: 1 | F10: Door Contact
A11: =Master!A233 -> Z740 | B11: =Master!B233 -> 0 | D11: 1 | F11: Door Contact
A12: =Master!A234 -> Z741 | B12: =Master!B234 -> 0 | D12: 1 | F12: Door Contact
A13: =Master!A235 -> Z742 | B13: =Master!B235 -> 0 | D13: 1 | F13: Door Contact
A14: =Master!A236 -> Z743 | B14: =Master!B236 -> 0 | D14: 1 | F14: Door Contact
A15: =Master!A237 -> Z744 | B15: =Master!B237 -> 0 | D15: 1 | F15: Door Contact
... A19: =Master!A241 -> Z748 | B19: =Master!B241 -> PS-15: BATT. TRBL. | D19: 1 | F19: SPARE
A20: Source: DMP 714-16 Expander #15
