Workbook

Sheet Header
B3: [SCHOOL NAME]
B4: [ADDRESS]
B5: [CITY, STATE ZIP]

Sheet Master
A2: XR-550 CONFIGURATION
A3: LOCATION
A4: POSITION | B4: DESCRIPTION
A5: AC
A6: Battery
A7: Bell
A8: Keypad Bus
A9: Ethernet
A10: SMK/GND
A11: LX500
A12: LX600
A13: LX700
A14: LX800
A15: LX900
A16: Z1
... A27: 710 BUS SPLITTER/REPEATER TOPOLOGY
A28: ID | B28: LOCATION | C28: SECTION TITLE | D28: COMBUS INPUT | E28: COMBUS OUTPUT 1 | F28: COMBUS OUTPUT 2 | G28: COMBUS OUTPUT 3
A29: 710-LX500-1
A30: 710-LX500-2
A31: 710-LX500-3
A32: 710-LX500-4
A33: 710-LX500-5
A34: 710-LX600-1
A35: 710-LX600-2
A36: 710-LX600-3
A37: 710-LX600-4
A38: 710-LX600-5
A39: 710-LX700-1
A40: 710-LX700-2
... A65: ZONE DATA
A66: ZONE # | B66: ZONE DESCRIPTION | C66: RSP/PS LOCATION | D66: 66 BLOCK LOCATION
A67: Z501
A68: Z502
A69: Z503
A70: Z504
A71: Z505
A72: Z506
A73: Z507
A74: Z508
A75: Z509
...

Sheet Terminal Cans
B2: =Header!B3 -> [SCHOOL NAME] | F2: =Header!B3 -> [SCHOOL NAME]
B3: =Header!B4 -> [ADDRESS] | F3: =Header!B4 -> [ADDRESS]
B4: =Header!B5 -> [CITY, STATE ZIP] | F4: =Header!B5 -> [CITY, STATE ZIP]
B7: =Master!D67 -> 0 | F7: =Master!D83 -> 0
B8: Pin 1 | C8: Pin 2 | D8: Description | F8: Pin 1 | G8: Pin 2 | H8: Description
B9: =Master!A67&" Field" -> Z501 Field | C9: =Master!A67&" Panel" -> Z501 Panel | D9: =Master!B67 -> 0 | F9: =Master!A83&" Field" -> Z517 Field | G9: =Master!A83&" Panel" -> Z517 Panel | H9: =Master!B83 -> 0
B10: =Master!A68&" Field" -> Z502 Field | C10: =Master!A68&" Panel" -> Z502 Panel | D10: =Master!B68 -> 0 | F10: =Master!A84&" Field" -> Z518 Field | G10: =Master!A84&" Panel" -> Z518 Panel | H10: =Master!B84 -> 0
B11: =Master!A69&" Field" -> Z503 Field | C11: =Master!A69&" Panel" -> Z503 Panel | D11: =Master!B69 -> 0 | F11: =Master!A85&" Field" -> Z519 Field | G11: =Master!A85&" Panel" -> Z519 Panel | H11: =Master!B85 -> 0
B12: =Master!A70&" Field" -> Z504 Field | C12: =Master!A70&" Panel" -> Z504 Panel | D12: =Master!B70 -> 0 | F12: =Master!A86&" Field" -> Z520 Field | G12: =Master!A86&" Panel" -> Z520 Panel | H12: =Master!B86 -> 0
B13: =Master!A71&" Field" -> Z505 Field | C13: =Master!A71&" Panel" -> Z505 Panel | D13: =Master!B71 -> 0 | F13: =Master!A87&" Field" -> Z521 Field | G13: =Master!A87&" Panel" -> Z521 Panel | H13: =Master!B87 -> 0
B14: =Master!A72&" Field" -> Z506 Field | C14: =Master!A72&" Panel" -> Z506 Panel | D14: =Master!B72 -> 0 | F14: =Master!A88&" Field" -> Z522 Field | G14: =Master!A88&" Panel" -> Z522 Panel | H14: =Master!B88 -> 0
B15: =Master!A73&" Field" -> Z507 Field | C15: =Master!A73&" Panel" -> Z507 Panel | D15: =Master!B73 -> 0 | F15: =Master!A89&" Field" -> Z523 Field | G15: =Master!A89&" Panel" -> Z523 Panel | H15: =Master!B89 -> 0
B16: =Master!A74&" Field" -> Z508 Field | C16: =Master!A74&" Panel" -> Z508 Panel | D16: =Master!B74 -> 0 | F16: =Master!A90&" Field" -> Z524 Field | G16: =Master!A90&" Panel" -> Z524 Panel | H16: =Master!B90 -> 0
B17: =Master!A75&" Field" -> Z509 Field | C17: =Master!A75&" Panel" -> Z509 Panel | D17: =Master!B75 -> 0 | F17: =Master!A91&" Field" -> Z525 Field | G17: =Master!A91&" Panel" -> Z525 Panel | H17: =Master!B91 -> 0
B18: =Master!A76&" Field" -> Z510 Field | C18: =Master!A76&" Panel" -> Z510 Panel | D18: =Master!B76 -> 0 | F18: =Master!A92&" Field" -> Z526 Field | G18: =Master!A92&" Panel" -> Z526 Panel | H18: =Master!B92 -> 0
B19: =Master!A77&" Field" -> Z511 Field | C19: =Master!A77&" Panel" -> Z511 Panel | D19: =Master!B77 -> 0 | F19: =Master!A93&" Field" -> Z527 Field | G19: =Master!A93&" Panel" -> Z527 Panel | H19: =Master!B93 -> 0
B20: =Master!A78&" Field" -> Z512 Field | C20: =Master!A78&" Panel" -> Z512 Panel | D20: =Master!B78 -> 0 | F20: =Master!A94&" Field" -> Z528 Field | G20: =Master!A94&" Panel" -> Z528 Panel | H20: =Master!B94 -> 0
... B24: =Master!A82&" Field" -> Z516 Field | C24: =Master!A82&" Panel" -> Z516 Panel | D24: =Master!B82 -> PS-1: BATT. TRBL. | F24: =Master!A98&" Field" -> Z532 Field | G24: =Master!A98&" Panel" -> Z532 Panel | H24: =Master!B98 -> PS-2: BATT. TRBL.
B25: AUX POWER | C25: PS1 | D25: POWER FROM POWER SUPPLY 1 | F25: AUX POWER | G25: PS2 | H25: POWER FROM POWER SUPPLY 2
B27: =Header!B3 -> [SCHOOL NAME] | F27: =Header!B3 -> [SCHOOL NAME]
B28: =Header!B4 -> [ADDRESS] | F28: =Header!B4 -> [ADDRESS]
B29: =Header!B5 -> [CITY, STATE ZIP] | F29: =Header!B5 -> [CITY, STATE ZIP]
B32: =Master!D99 -> 0 | F32: =Master!D115 -> 0
B33: Pin 1 | C33: Pin 2 | D33: Description | F33: Pin 1 | G33: Pin 2 | H33: Description
B34: =Master!A99&" Field" -> Z533 Field | C34: =Master!A99&" Panel" -> Z533 Panel | D34: =Master!B99 -> 0 | F34: =Master!A115&" Field" -> Z549 Field | G34: =Master!A115&" Panel" -> Z549 Panel | H34: =Master!B115 -> 0
B35: =Master!A100&" Field" -> Z534 Field | C35: =Master!A100&" Panel" -> Z534 Panel | D35: =Master!B100 -> 0 | F35: =Master!A116&" Field" -> Z550 Field | G35: =Master!A116&" Panel" -> Z550 Panel | H35: =Master!B116 -> 0
B36: =Master!A101&" Field" -> Z535 Field | C36: =Master!A101&" Panel" -> Z535 Panel | D36: =Master!B101 -> 0 | F36: =Master!A117&" Field" -> Z551 Field | G36: =Master!A117&" Panel" -> Z551 Panel | H36: =Master!B117 -> 0
B37: =Master!A102&" Field" -> Z536 Field | C37: =Master!A102&" Panel" -> Z536 Panel | D37: =Master!B102 -> 0 | F37: =Master!A118&" Field" -> Z552 Field | G37: =Master!A118&" Panel" -> Z552 Panel | H37: =Master!B118 -> 0
B38: =Master!A103&" Field" -> Z537 Field | C38: =Master!A103&" Panel" -> Z537 Panel | D38: =Master!B103 -> 0 | F38: =Master!A119&" Field" -> Z553 Field | G38: =Master!A119&" Panel" -> Z553 Panel | H38: =Master!B119 -> 0
B39: =Master!A104&" Field" -> Z538 Field | C39: =Master!A104&" Panel" -> Z538 Panel | D39: =Master!B104 -> 0 | F39: =Master!A120&" Field" -> Z554 Field | G39: =Master!A120&" Panel" -> Z554 Panel | H39: =Master!B120 -> 0
B40: =Master!A105&" Field" -> Z539 Field | C40: =Master!A105&" Panel" -> Z539 Panel | D40: =Master!B105 -> 0 | F40: =Master!A121&" Field" -> Z555 Field | G40: =Master!A121&" Panel" -> Z555 Panel | H40: =Master!B121 -> 0
B41: =Master!A106&" Field" -> Z540 Field | C41: =Master!A106&" Panel" -> Z540 Panel | D41: =Master!B106 -> 0 | F41: =Master!A122&" Field" -> Z556 Field | G41: =Master!A122&" Panel" -> Z556 Panel | H41: =Master!B122 -> 0
B42: =Master!A107&" Field" -> Z541 Field | C42: =Master!A107&" Panel" -> Z541 Panel | D42: =Master!B107 -> 0 | F42: =Master!A123&" Field" -> Z557 Field | G42: =Master!A123&" Panel" -> Z557 Panel | H42: =Master!B123 -> 0
B43: =Master!A108&" Field" -> Z542 Field | C43: =Master!A108&" Panel" -> Z542 Panel | D43: =Master!B108 -> 0 | F43: =Master!A124&" Field" -> Z558 Field | G43: =Master!A124&" Panel" -> Z558 Panel | H43: =Master!B124 -> 0
B44: =Master!A109&" Field" -> Z543 Field | C44: =Master!A109&" Panel" -> Z543 Panel | D44: =Master!B109 -> 0 | F44: =Master!A125&" Field" -> Z559 Field | G44: =Master!A125&" Panel" -> Z559 Panel | H44: =Master!B125 -> 0
B45: =Master!A110&" Field" -> Z544 Field | C45: =Master!A110&" Panel" -> Z544 Panel | D45: =Master!B110 -> 0 | F45: =Master!A126&" Field" -> Z560 Field | G45: =Master!A126&" Panel" -> Z560 Panel | H45: =Master!B126 -> 0
... B49: =Master!A114&" Field" -> Z548 Field | C49: =Master!A114&" Panel" -> Z548 Panel | D49: =Master!B114 -> PS-3: BATT. TRBL. | F49: =Master!A130&" Field" -> Z564 Field | G49: =Master!A130&" Panel" -> Z564 Panel | H49: =Master!B130 -> PS-4: BATT. TRBL.
B50: AUX POWER | C50: PS3 | D50: POWER FROM POWER SUPPLY 3 | F50: AUX POWER | G50: PS4 | H50: POWER FROM POWER SUPPLY 4
B52: =Header!B3 -> [SCHOOL NAME] | F52: =Header!B3 -> [SCHOOL NAME]
B53: =Header!B4 -> [ADDRESS] | F53: =Header!B4 -> [ADDRESS]
...

Sheet RSPs
B2: =Header!B3 -> [SCHOOL NAME] | F2: =Header!B3 -> [SCHOOL NAME]
B3: =Header!B4 -> [ADDRESS] | F3: =Header!B4 -> [ADDRESS]
B4: =Header!B5 -> [CITY, STATE ZIP] | F4: =Header!B5 -> [CITY, STATE ZIP]
B7: =Master!C67 -> 0 | F7: =Master!C83 -> 0
B8: Position | C8: Zones | D8: Description | F8: Position | G8: Zones | H8: Description
B9: Combus | C9: Zone No. | D9: Combus to MSP | F9: Combus | G9: Zone No. | H9: Combus to MSP
B10: 1 | C10: =Master!A67 -> Z501 | D10: =Master!B67 -> 0 | F10: 1 | G10: =Master!A83 -> Z517 | H10: =Master!B83 -> 0
B11: 2 | C11: =Master!A68 -> Z502 | D11: =Master!B68 -> 0 | F11: 2 | G11: =Master!A84 -> Z518 | H11: =Master!B84 -> 0
B12: 3 | C12: =Master!A69 -> Z503 | D12: =Master!B69 -> 0 | F12: 3 | G12: =Master!A85 -> Z519 | H12: =Master!B85 -> 0
B13: 4 | C13: =Master!A70 -> Z504 | D13: =Master!B70 -> 0 | F13: 4 | G13: =Master!A86 -> Z520 | H13: =Master!B86 -> 0
B14: 5 | C14: =Master!A71 -> Z505 | D14: =Master!B71 -> 0 | F14: 5 | G14: =Master!A87 -> Z521 | H14: =Master!B87 -> 0
B15: 6 | C15: =Master!A72 -> Z506 | D15: =Master!B72 -> 0 | F15: 6 | G15: =Master!A88 -> Z522 | H15: =Master!B88 -> 0
B16: 7 | C16: =Master!A73 -> Z507 | D16: =Master!B73 -> 0 | F16: 7 | G16: =Master!A89 -> Z523 | H16: =Master!B89 -> 0
B17: 8 | C17: =Master!A74 -> Z508 | D17: =Master!B74 -> 0 | F17: 8 | G17: =Master!A90 -> Z524 | H17: =Master!B90 -> 0
B18: 9 | C18: =Master!A75 -> Z509 | D18: =Master!B75 -> 0 | F18: 9 | G18: =Master!A91 -> Z525 | H18: =Master!B91 -> 0
B19: 10 | C19: =Master!A76 -> Z510 | D19: =Master!B76 -> 0 | F19: 10 | G19: =Master!A92 -> Z526 | H19: =Master!B92 -> 0
B20: 11 | C20: =Master!A77 -> Z511 | D20: =Master!B77 -> 0 | F20: 11 | G20: =Master!A93 -> Z527 | H20: =Master!B93 -> 0
B21: 12 | C21: =Master!A78 -> Z512 | D21: =Master!B78 -> 0 | F21: 12 | G21: =Master!A94 -> Z528 | H21: =Master!B94 -> 0
... B25: 16 | C25: =Master!A82 -> Z516 | D25: =Master!B82 -> PS-1: BATT. TRBL. | F25: 16 | G25: =Master!A98 -> Z532 | H25: =Master!B98 -> PS-2: BATT. TRBL.
B28: =Header!B3 -> [SCHOOL NAME] | F28: =Header!B3 -> [SCHOOL NAME]
B29: =Header!B4 -> [ADDRESS] | F29: =Header!B4 -> [ADDRESS]
B30: =Header!B5 -> [CITY, STATE ZIP] | F30: =Header!B5 -> [CITY, STATE ZIP]
B33: =Master!C99 -> 0 | F33: =Master!C163 -> 0
B34: Position | C34: Zones | D34: Description | F34: Position | G34: Zones | H34: Description
B35: Combus | C35: Zone No. | D35: Combus to MSP | F35: Combus | G35: Zone No. | H35: Combus to MSP
B36: 1 | C36: =Master!A99 -> Z533 | D36: =Master!B99 -> 0 | F36: 1 | G36: =Master!A115 -> Z549 | H36: =Master!B115 -> 0
B37: 2 | C37: =Master!A100 -> Z534 | D37: =Master!B100 -> 0 | F37: 2 | G37: =Master!A116 -> Z550 | H37: =Master!B116 -> 0
B38: 3 | C38: =Master!A101 -> Z535 | D38: =Master!B101 -> 0 | F38: 3 | G38: =Master!A117 -> Z551 | H38: =Master!B117 -> 0
B39: 4 | C39: =Master!A102 -> Z536 | D39: =Master!B102 -> 0 | F39: 4 | G39: =Master!A118 -> Z552 | H39: =Master!B118 -> 0
B40: 5 | C40: =Master!A103 -> Z537 | D40: =Master!B103 -> 0 | F40: 5 | G40: =Master!A119 -> Z553 | H40: =Master!B119 -> 0
B41: 6 | C41: =Master!A104 -> Z538 | D41: =Master!B104 -> 0 | F41: 6 | G41: =Master!A120 -> Z554 | H41: =Master!B120 -> 0
B42: 7 | C42: =Master!A105 -> Z539 | D42: =Master!B105 -> 0 | F42: 7 | G42: =Master!A121 -> Z555 | H42: =Master!B121 -> 0
B43: 8 | C43: =Master!A106 -> Z540 | D43: =Master!B106 -> 0 | F43: 8 | G43: =Master!A122 -> Z556 | H43: =Master!B122 -> 0
B44: 9 | C44: =Master!A107 -> Z541 | D44: =Master!B107 -> 0 | F44: 9 | G44: =Master!A123 -> Z557 | H44: =Master!B123 -> 0
B45: 10 | C45: =Master!A108 -> Z542 | D45: =Master!B108 -> 0 | F45: 10 | G45: =Master!A124 -> Z558 | H45: =Master!B124 -> 0
B46: 11 | C46: =Master!A109 -> Z543 | D46: =Master!B109 -> 0 | F46: 11 | G46: =Master!A125 -> Z559 | H46: =Master!B125 -> 0
B47: 12 | C47: =Master!A110 -> Z544 | D47: =Master!B110 -> 0 | F47: 12 | G47: =Master!A126 -> Z560 | H47: =Master!B126 -> 0
... B51: 16 | C51: =Master!A114 -> Z548 | D51: =Master!B114 -> PS-3: BATT. TRBL. | F51: 16 | G51: =Master!A130 -> Z564 | H51: =Master!B130 -> PS-4: BATT. TRBL.
B54: =Header!B3 -> [SCHOOL NAME] | F54: =Header!B3 -> [SCHOOL NAME]
B55: =Header!B4 -> [ADDRESS] | F55: =Header!B4 -> [ADDRESS]
...

Sheet Power Supplies
B2: =Header!B3 -> [SCHOOL NAME] | E2: =Header!B3 -> [SCHOOL NAME]
B3: =Header!B4 -> [ADDRESS] | E3: =Header!B4 -> [ADDRESS]
B4: =Header!B5 -> [CITY, STATE ZIP] | E4: =Header!B5 -> [CITY, STATE ZIP]
B7: =Master!C81 -> 0 | E7: =Master!C97 -> 0
B8: Position | C8: Description | E8: Position | F8: Description
B9: AC Trouble | C9: ="RSP-1 "&Master!A81 -> RSP-1 Z515 | E9: AC Trouble | F9: ="RSP-2 "&Master!A97 -> RSP-2 Z531
B10: Batt. Trouble | C10: ="RSP-1 "&Master!A82 -> RSP-1 Z516 | E10: Batt. Trouble | F10: ="RSP-2 "&Master!A98 -> RSP-2 Z532
B11: DC | C11: 66 block | E11: DC | F11: 66 block
B12: Battery | C12: 12v Battery | E12: Battery | F12: 12v Battery
B14: =Header!B3 -> [SCHOOL NAME] | E14: =Header!B3 -> [SCHOOL NAME]
B15: =Header!B4 -> [ADDRESS] | E15: =Header!B4 -> [ADDRESS]
B16: =Header!B5 -> [CITY, STATE ZIP] | E16: =Header!B5 -> [CITY, STATE ZIP]
B19: =Master!C113 -> 0 | E19: =Master!C129 -> 0
B20: Position | C20: Description | E20: Position | F20: Description
B21: AC Trouble | C21: ="RSP-3 "&Master!A113 -> RSP-3 Z547 | E21: AC Trouble | F21: ="RSP-4 "&Master!A129 -> RSP-4 Z563
B22: Batt. Trouble | C22: ="RSP-3 "&Master!A114 -> RSP-3 Z548 | E22: Batt. Trouble | F22: ="RSP-4 "&Master!A130 -> RSP-4 Z564
B23: DC | C23: 66 block | E23: DC | F23: 66 block
B24: Battery | C24: 12v Battery | E24: Battery | F24: 12v Battery
B26: =Header!B3 -> [SCHOOL NAME] | E26: =Header!B3 -> [SCHOOL NAME]
B27: =Header!B4 -> [ADDRESS] | E27: =Header!B4 -> [ADDRESS]
B28: =Header!B5 -> [CITY, STATE ZIP] | E28: =Header!B5 -> [CITY, STATE ZIP]
B31: =Master!C145 -> 0 | E31: =Master!C161 -> 0
B32: Position | C32: Description | E32: Position | F32: Description
B33: AC Trouble | C33: ="RSP-5 "&Master!A145 -> RSP-5 Z579 | E33: AC Trouble | F33: ="RSP-6 "&Master!A161 -> RSP-6 Z595
B34: Batt. Trouble | C34: ="RSP-5 "&Master!A146 -> RSP-5 Z580 | E34: Batt. Trouble | F34: ="RSP-6 "&Master!A162 -> RSP-6 Z596
B35: DC | C35: 66 block | E35: DC | F35: 66 block
B36: Battery | C36: 12v Battery | E36: Battery | F36: 12v Battery
B38: =Header!B3 -> [SCHOOL NAME] | E38: =Header!B3 -> [SCHOOL NAME]
B39: =Header!B4 -> [ADDRESS] | E39: =Header!B4 -> [ADDRESS]
B40: =Header!B5 -> [CITY, STATE ZIP] | E40: =Header!B5 -> [CITY, STATE ZIP]
B43: =Master!C181 -> 0 | E43: =Master!C197 -> 0
B44: Position | C44: Description | E44: Position | F44: Description
B45: AC Trouble | C45: ="RSP-7 "&Master!A181 -> RSP-7 Z615 | E45: AC Trouble | F45: ="RSP-8 "&Master!A197 -> RSP-8 Z631
B46: Batt. Trouble | C46: ="RSP-7 "&Master!A182 -> RSP-7 Z616 | E46: Batt. Trouble | F46: ="RSP-8 "&Master!A198 -> RSP-8 Z632
B47: DC | C47: 66 block | E47: DC | F47: 66 block
B48: Battery | C48: 12v Battery | E48: Battery | F48: 12v Battery
B50: =Header!B3 -> [SCHOOL NAME] | E50: =Header!B3 -> [SCHOOL NAME]
B51: =Header!B4 -> [ADDRESS] | E51: =Header!B4 -> [ADDRESS]
B52: =Header!B5 -> [CITY, STATE ZIP] | E52: =Header!B5 -> [CITY, STATE ZIP]
B55: =Master!C213 -> 0 | E55: =Master!C229 -> 0
...

Sheet LX-KP-710s
B2: =Header!B3 -> [SCHOOL NAME] | E2: =Header!B3 -> [SCHOOL NAME]
B3: =Header!B4 -> [ADDRESS] | E3: =Header!B4 -> [ADDRESS]
B4: =Header!B5 -> [CITY, STATE ZIP] | E4: =Header!B5 -> [CITY, STATE ZIP]
B7: =Master!C29 -> 0 | E7: =Master!C30 -> 0
B8: Position | C8: Description | E8: Position | F8: Description
B9: Combus Input | C9: =Master!D29 -> 0 | E9: Combus Input | F9: =Master!D30 -> 0
B10: Combus Output 1 | C10: =Master!E29 -> 0 | E10: Combus Output 1 | F10: =Master!E30 -> 0
B11: Combus Output 2 | C11: =Master!F29 -> 0 | E11: Combus Output 2 | F11: =Master!F30 -> 0
B12: Combus Output 3 | C12: =Master!G29 -> 0 | E12: Combus Output 3 | F12: =Master!G30 -> 0
B14: =Header!B3 -> [SCHOOL NAME] | E14: =Header!B3 -> [SCHOOL NAME]
B15: =Header!B4 -> [ADDRESS] | E15: =Header!B4 -> [ADDRESS]
B16: =Header!B5 -> [CITY, STATE ZIP] | E16: =Header!B5 -> [CITY, STATE ZIP]
B19: =Master!C31 -> 0 | E19: =Master!C32 -> 0
B20: Position | C20: Description | E20: Position | F20: Description
B21: Combus Input | C21: =Master!D31 -> 0 | E21: Combus Input | F21: =Master!D32 -> 0
B22: Combus Output 1 | C22: =Master!E31 -> 0 | E22: Combus Output 1 | F22: =Master!E32 -> 0
B23: Combus Output 2 | C23: =Master!F31 -> 0 | E23: Combus Output 2 | F23: =Master!F32 -> 0
B24: Combus Output 3 | C24: =Master!G31 -> 0 | E24: Combus Output 3 | F24: =Master!G32 -> 0
B26: =Header!B3 -> [SCHOOL NAME] | E26: =Header!B3 -> [SCHOOL NAME]
B27: =Header!B4 -> [ADDRESS] | E27: =Header!B4 -> [ADDRESS]
B28: =Header!B5 -> [CITY, STATE ZIP] | E28: =Header!B5 -> [CITY, STATE ZIP]
B31: =Master!C34 -> 0 | E31: =Master!C35 -> 0
B32: Position | C32: Description | E32: Position | F32: Description
B33: Combus Input | C33: =Master!D34 -> 0 | E33: Combus Input | F33: =Master!D35 -> 0
B34: Combus Output 1 | C34: =Master!E34 -> 0 | E34: Combus Output 1 | F34: =Master!E35 -> 0
B35: Combus Output 2 | C35: =Master!F34 -> 0 | E35: Combus Output 2 | F35: =Master!F35 -> 0
B36: Combus Output 3 | C36: =Master!G34 -> 0 | E36: Combus Output 3 | F36: =Master!G35 -> 0
B38: =Header!B39 -> 0 | E38: =Header!B39 -> 0
B39: =Header!B40 -> 0 | E39: =Header!B40 -> 0
B40: =Header!B41 -> 0 | E40: =Header!B41 -> 0
B43: =Master!C36 -> 0 | E43: =Master!C37 -> 0
B44: Position | C44: Description | E44: Position | F44: Description
B45: Combus Input | C45: =Master!D36 -> 0 | E45: Combus Input | F45: =Master!D37 -> 0
B46: Combus Output 1 | C46: =Master!E36 -> 0 | E46: Combus Output 1 | F46: =Master!E37 -> 0
B47: Combus Output 2 | C47: =Master!F36 -> 0 | E47: Combus Output 2 | F47: =Master!F37 -> 0
B48: Combus Output 3 | C48: =Master!G36 -> 0 | E48: Combus Output 3 | F48: =Master!G37 -> 0
B50: =Header!B39 -> 0 | E50: =Header!B39 -> 0
B51: =Header!B40 -> 0 | E51: =Header!B40 -> 0
B52: =Header!B41 -> 0 | E52: =Header!B41 -> 0
B55: =Master!C39 -> 0 | E55: =Master!C40 -> 0
...
